Traceback (most recent call last):
  File "C:\Users\wnaashok\PycharmProjects\Procurability_Report\.venv\Scripts\Procurability_Report.py", line 124, in <module>
    df = pd.DataFrame(results)
         ^^^^^^^^^^^^^^^^^^^^^
  File "C:\Users\wnaashok\PycharmProjects\Procurability_Report\.venv\Lib\site-packages\pandas\core\frame.py", line 851, in __init__
    arrays, columns, index = nested_data_to_arrays(
                             ^^^^^^^^^^^^^^^^^^^^^^
  File "C:\Users\wnaashok\PycharmProjects\Procurability_Report\.venv\Lib\site-packages\pandas\core\internals\construction.py", line 520, in nested_data_to_arrays
    arrays, columns = to_arrays(data, columns, dtype=dtype)
                      ^^^^^^^^^^^^^^^^^^^^^^^^^^^^^^^^^^^^^
  File "C:\Users\wnaashok\PycharmProjects\Procurability_Report\.venv\Lib\site-packages\pandas\core\internals\construction.py", line 837, in to_arrays
    arr, columns = _list_of_dict_to_arrays(data, columns)
                   ^^^^^^^^^^^^^^^^^^^^^^^^^^^^^^^^^^^^^^
  File "C:\Users\wnaashok\PycharmProjects\Procurability_Report\.venv\Lib\site-packages\pandas\core\internals\construction.py", line 917, in _list_of_dict_to_arrays
    pre_cols = lib.fast_unique_multiple_list_gen(gen, sort=sort)
               ^^^^^^^^^^^^^^^^^^^^^^^^^^^^^^^^^^^^^^^^^^^^^^^^^
  File "lib.pyx", line 367, in pandas._libs.lib.fast_unique_multiple_list_gen
  File "C:\Users\wnaashok\PycharmProjects\Procurability_Report\.venv\Lib\site-packages\pandas\core\internals\construction.py", line 915, in <genexpr>
    gen = (list(x.keys()) for x in data)
                ^^^^^^
AttributeError: 'NoneType' object has no attribute 'keys'
